<?xml version="1.0"?>
<robot xmlns:xacro="http://www.ros.org/wiki/xacro" name="manip">
  <link name="zero_base">
  </link>
  <joint name="joint0" type="continuous">
    <origin xyz="0 0 0" rpy="0 0 0"/>
    <parent link="zero_base"/>
    <axis xyz="0 0 1"/>
    <child link="link1"/>
    <dynamics damping="0.05"/>
  </joint>


  <link name="link1">
    <visual>
      <geometry>
        <cylinder length="0.06" radius="0.1"/>
      </geometry>
      <origin xyz="0 0 0.04"/>
      <material name="blue">
	<color rgba="0 0 0.8 1"/>
      </material>
    </visual>
    <collision>
      <geometry>
        <cylinder length="0.06" radius="0.1"/>
      </geometry>
      <origin xyz="0 0 0.04"/>
    </collision>
    <inertial>
      <mass value="1"/>
      <inertia ixx="1e-3" ixy="0.0" ixz="0.0" iyy="1e-3" iyz="0.0" izz="1e-3"/>
    </inertial>
  </link>


  <joint name="joint1" type="continuous">
    <origin xyz="0 0 0.08" rpy="0 0 0"/>
    <parent link="link1"/>
    <axis xyz="1 0 0"/>
    <child link="link2"/>
    <dynamics damping="0.05"/>
  </joint>


  <link name="link2">
    <visual>
      <geometry>
        <cylinder length="0.4" radius="0.02"/>
      </geometry>
      <origin xyz="0 0 0.29"/>
      <material name="blue">
	<color rgba="0 0 .8 1"/>
      </material>
    </visual>
    <collision>
      <geometry>
        <cylinder length="0.4" radius="0.02"/>
      </geometry>
      <origin xyz="0 0 0.29"/>
    </collision>
    <inertial>
      <mass value="0.2"/>
      <inertia ixx="1e-3" ixy="0.0" ixz="0.0" iyy="1e-3" iyz="0.0" izz="1e-3"/>
    </inertial>
   </link>


 <joint name="joint2" type="continuous">
    <origin xyz="0.015 0 0.495" rpy="0 0 0"/>
    <parent link="link2"/>
    <axis xyz="1 0 0"/>
    <child link="link3"/>
    <dynamics damping="0.05"/>
  </joint>


    <link name="link3">
    <visual>
      <geometry>
        <cylinder length="0.4" radius="0.02"/>
      </geometry>
      <origin xyz="0.165 0 0.64" rpy="0 ${3.141692/4} 0"/>
      <material name="blue">
	<color rgba="0 0 0.8 1"/>
      </material>
    </visual>
    <collision>
      <geometry>
        <cylinder length="0.4" radius="0.02"/>
      </geometry>
      <origin xyz="0.165 0 0.64"  rpy="0 ${3.141692/4} 0"/>
    </collision>
    <inertial>
      <mass value="0.2"/>
      <inertia ixx="1e-3" ixy="0.0" ixz="0.0" iyy="1e-3" iyz="0.0" izz="1e-3"/>
    </inertial>
  </link>


  <joint name="joint3" type="continuous">
    <origin xyz="0.325 0 0.775" rpy="0 ${3.141692/4} 0"/>
    <parent link="link3"/>
    <axis xyz="1 0 0"/>
    <child link="link4"/>
    <dynamics damping="0.05"/>
  </joint>


    <link name="link4">
    <visual>
      <geometry>
        <cylinder length="0.3" radius="0.02"/>
      </geometry>
      <origin xyz="0.49 0 0.775" rpy="0 ${3.141692/2} 0"/>
      <material name="blue">
	<color rgba="0 0 0.8 1"/>
      </material>
    </visual>
    <collision>
      <geometry>
        <cylinder length="0.3" radius="0.02"/>
      </geometry>
      <origin xyz="0.49 0 0.775"  rpy="0 ${3.141692/2} 0"/>
    </collision>
    <inertial>
      <mass value="0.2"/>
      <inertia ixx="1e-3" ixy="0.0" ixz="0.0" iyy="1e-3" iyz="0.0" izz="1e-3"/>
    </inertial>
  </link>

 
  
  
  <gazebo reference="link1">
    <material>Gazebo/Blue</material>
    <mu1>0</mu1>
    <mu2>0</mu2>
  </gazebo>
  <gazebo reference="link2">
    <material>Gazebo/Blue</material>
    <mu1>0</mu1>
    <mu2>0</mu2>
  </gazebo>
  <gazebo reference="link3">
    <material>Gazebo/Blue</material>
    <mu1>0</mu1>
    <mu2>0</mu2>
  </gazebo>
  <gazebo reference="link4">
    <material>Gazebo/Blue</material>
    <mu1>0</mu1>
    <mu2>0</mu2>
  </gazebo>
  <transmission name="j1_trans">
    <type>transmission_interface/SimpleTransmission</type>
    <joint name="joint1">
      <hardwareInterface>EffortJointInterface</hardwareInterface>
    </joint>
    <actuator name="motor1">
      <mechanicalReduction>1</mechanicalReduction>
      <hardwareInterface>EffortJointInterface</hardwareInterface>
    </actuator>
  </transmission>
  <transmission name="j2_trans">
    <type>transmission_interface/SimpleTransmission</type>
    <joint name="joint2">
      <hardwareInterface>EffortJointInterface</hardwareInterface>
    </joint>
    <actuator name="motor2">
      <mechanicalReduction>1</mechanicalReduction>
      <hardwareInterface>EffortJointInterface</hardwareInterface>
    </actuator>
  </transmission>
  <transmission name="j3_trans">
    <type>transmission_interface/SimpleTransmission</type>
    <joint name="joint3">
      <hardwareInterface>EffortJointInterface</hardwareInterface>
    </joint>
    <actuator name="motor3">
      <mechanicalReduction>1</mechanicalReduction>
      <hardwareInterface>EffortJointInterface</hardwareInterface>
    </actuator>
  </transmission>
  
    <plugin name="gazebo_ros_control" filename="libgazebo_ros_control.so">
      <robotNamespace>/manip</robotNamespace>
    </plugin>
</robot>
